Workbook

Sheet Cover Page
C7: CYBERSHIELD360
C8: Protecting Businesses. Empowering Growth.
B13: THREE-YEAR FINANCIAL MODEL
B14: AI-Powered Cybersecurity Management Platform for Startups, SMEs & Growing Organizations
B16: DOCUMENT INFORMATION
B17: Industry | C17: Cybersecurity / Enterprise SaaS
B18: Business Model | C18: Subscription-based Cybersecurity Management Platform (SaaS)
B19: Prepared For | C19: MBA / MBM Portfolio, Startup Documentation & Investor Presentation
B20: Prepared By | C20: CyberShield360 Founding Team (Financial Model by AI Financial Analyst)
B21: Version | C21: 1.0
B22: Date | C22: 05 July 2026
B23: Currency | C23: Indian Rupees (₹) unless otherwise stated
B26: IMPORTANT NOTE: All financial projections, cost estimates, and scenario figures in this workbook are ILLUSTRATIVE, prepared for MBA/MBM portfolio, startup-competition, and business-portfolio documentation purposes. Subscriber growth (400 / 1,600 / 4,200 across Years 1-3) and pricing are sourced directly from CyberShield360's Business Plan and Investor Presentation (2026). Cost, unit-economics, and financing figures not explicitly stated in source materials are clearly flagged as illustrative planning assumptions and are editable on the Assumptions sheet. Figures are not audited and should not be relied upon for actual investment decisions without independent verification.
B33: WORKBOOK CONTENTS
B34: 1. Cover Page
B35: 2. Assumptions
B36: 3. Startup Cost Estimation
B37: 4. Revenue Projection
B38: 5. Profit & Loss Statement
B39: 6. Cash Flow Statement
B40: 7. Break-even Analysis
B41: 8. KPI Dashboard
B42: 9. Scenario Analysis
B43: 10. Investment Summary

Sheet Assumptions
B1: CYBERSHIELD360 — MODEL ASSUMPTIONS
B2: Blue cells are editable inputs. All figures in Indian Rupees (₹) unless stated. Sources noted in column F.
B4: A. SUBSCRIPTION PRICING (Source: Business Plan Ch.27 / Investor Deck p.11)
B5: Plan | C5: Price (₹/month) | F5: Notes
B6: Starter Shield | C6: 499 | F6: Entry tier; billed monthly
B7: Business Shield (Most Popular) | C7: 1499 | F7: Primary revenue driver; mix shifts toward this tier over time
B8: Enterprise Shield | C8: Custom pricing | F8: Modelled as upside only; excluded from baseline revenue per source docs
B10: B. SUBSCRIBER GROWTH — YEAR-END COUNTS (Source: Investor Deck p.14 / Business Plan Ch.35)
B11: Segment | C11: Year 1 | D11: Year 2 | E11: Year 3 | F11: Notes
B12: Starter Shield subscribers | C12: 300 | D12: 880 | E12: 1680
B13: Business Shield subscribers | C13: 100 | D13: 720 | E13: 2520
B14: Total subscribers (year-end) | C14: =C12+C13 -> 400 | D14: =D12+D13 -> 1600 | E14: =E12+E13 -> 4200 | F14: Matches 400 / 1,600 / 4,200 stated in source materials
B16: C. REVENUE MIX / ADD-ON ASSUMPTIONS (Source: Business Plan Ch.26)
B17: Item | C17: Year 1 | D17: Year 2 | E17: Year 3 | F17: Notes
B18: Consulting & training add-on (% of subscription revenue) | C18: 0 | D18: 0.05 | E18: 0.1 | F18: Cross-sold to existing base; grows as base matures
B20: D. OPERATING COST ASSUMPTIONS — ANNUAL (Source: Business Plan Ch.35)
B21: Cost Category | C21: Year 1 | D21: Year 2 | E21: Year 3 | F21: Notes
B22: Team costs (salaries, founder comp.) | C22: 6400000 | D22: 12600000 | E22: 20000000
B23: Cloud infrastructure & hosting (COGS) | C23: 600000 | D23: 1500000 | E23: 2800000
B24: Marketing & channel enablement | C24: 800000 | D24: 2000000 | E24: 3000000
B25: General & administrative / legal / compliance | C25: 500000 | D25: 1000000 | E25: 1500000
B26: Total estimated operating cost | C26: =SUM(C22:C25) -> 8300000 | D26: =SUM(D22:D25) -> 17100000 | E26: =SUM(E22:E25) -> 27300000
B28: E. UNIT ECONOMICS ASSUMPTIONS
B29: Metric | C29: Value | F29: Notes
B30: Blended ARPU, early period (₹/month) | C30: 750 | F30: Source: Business Plan Ch.36 (Break-even Analysis)
B31: Variable cost per subscriber (₹/month) | C31: 100 | F31: Hosting, payment processing, support — Source: Business Plan Ch.36
B32: Contribution margin per subscriber (₹/month) | C32: =C30-C31 -> 650
B33: Estimated monthly churn rate | C33: 0.03 | F33: Illustrative planning assumption — not stated in source docs; editable
B34: Assumed gross margin (for LTV calc) | C34: 0.85 | F34: Illustrative SaaS-typical gross margin assumption; editable
B35: Customer Lifetime Value (LTV) | C35: =C30*C34/C33 -> 21250 | F35: LTV = ARPU x Gross Margin / Monthly Churn Rate
B37: F. FINANCIAL & MACRO ASSUMPTIONS (Illustrative — editable)
B38: Metric | C38: Value | F38: Notes
B39: Corporate tax rate | C39: 0.25 | F39: Illustrative effective rate for an early-stage Indian startup
B40: Discount rate (VC hurdle rate) | C40: 0.18 | F40: Illustrative early-stage venture discount rate
B41: Annual inflation rate | C41: 0.05 | F41: Illustrative — informational only; not applied to fixed cost inputs above
B42: Depreciation period for startup capex (years) | C42: 5 | F42: Straight-line, applied to Product Dev + Cloud Setup + Branding capex
B43: Assumed Year 4+ annual revenue growth rate | C43: 0.4 | F43: Illustrative — used only for Investment Summary indicative ROI extrapolation
B45: G. SCENARIO MULTIPLIERS (applied to subscriber growth — see Scenario Analysis)
B46: Scenario | C46: Multiplier vs. Expected Case | F46: Notes
B47: Best Case | C47: 1.2
...

Sheet Startup Cost Estimation
B1: STARTUP COST ESTIMATION
B2: One-time capital required to bring CyberShield360 from concept to launch-ready MVP. Source: Business Plan Ch.34.
B4: Cost Category | C4: Estimated Cost (₹)
B5: Product development (platform, mobile app, initial AI models) | C5: 2500000
B6: Cloud infrastructure setup | C6: 400000
B7: Branding, website & marketing collateral | C7: 300000
B8: Legal, compliance & incorporation | C8: 200000
B9: Founding team runway (approx. 6 months) | C9: 1500000
B10: Initial marketing launch budget | C10: 500000
B11: Subtotal | C11: =SUM(C5:C10) -> 5400000
B12: Contingency (~10%) | C12: 0.1 | E12: Applied to subtotal above
B13: Contingency amount | C13: =C11*C12 -> 540000
B14: TOTAL ESTIMATED STARTUP COST | C14: =C11+C13 -> 5940000
B16: Product development is the single largest line item, reflecting that core value is embedded in software and the AI scoring engine rather than physical assets. Contingency reflects ordinary first-time platform-development and launch-timeline uncertainty.

Sheet Revenue Projection
B1: REVENUE PROJECTION — 36-MONTH BUILD
B2: Monthly subscriber counts interpolate linearly between the year-end anchors on the Assumptions sheet (400 / 1,600 / 4,200 subscribers). Enterprise licensing is modelled as upside and excluded from baseline, consistent with source materials.
B4: Month | C4: Year | D4: Starter Subs | E4: Business Subs | F4: Total Subs | G4: Starter Revenue (₹) | H4: Business Revenue (₹) | I4: Subscription Revenue (₹) | J4: Consulting & Training Add-on (₹) | K4: Total Revenue (₹)
B5: 1 | C5: Y1 | D5: =IF(B5<=12,Assumptions!$C$12*B5/12,IF(B5<=24,Assumptions!$C$12+(Assumptions!$D$12-Assumptions!$C$12)*(B5-12)/12,Assumptions!$D$12+(Assumptions!$E$12-Assumptions!$D$12)*(B5-24)/12)) -> 25 | E5: =IF(B5<=12,Assumptions!$C$13*B5/12,IF(B5<=24,Assumptions!$C$13+(Assumptions!$D$13-Assumptions!$C$13)*(B5-12)/12,Assumptions!$D$13+(Assumptions!$E$13-Assumptions!$D$13)*(B5-24)/12)) -> 8.3333333 | F5: =D5+E5 -> 33.333333 | G5: =D5*Assumptions!$C$6 -> 12475 | H5: =E5*Assumptions!$C$7 -> 12491.667 | I5: =G5+H5 -> 24966.667 | J5: =I5*Assumptions!$C$18 -> 0 | K5: =I5+J5 -> 24966.667
B6: 2 | C6: Y1 | D6: =IF(B6<=12,Assumptions!$C$12*B6/12,IF(B6<=24,Assumptions!$C$12+(Assumptions!$D$12-Assumptions!$C$12)*(B6-12)/12,Assumptions!$D$12+(Assumptions!$E$12-Assumptions!$D$12)*(B6-24)/12)) -> 50 | E6: =IF(B6<=12,Assumptions!$C$13*B6/12,IF(B6<=24,Assumptions!$C$13+(Assumptions!$D$13-Assumptions!$C$13)*(B6-12)/12,Assumptions!$D$13+(Assumptions!$E$13-Assumptions!$D$13)*(B6-24)/12)) -> 16.666667 | F6: =D6+E6 -> 66.666667 | G6: =D6*Assumptions!$C$6 -> 24950 | H6: =E6*Assumptions!$C$7 -> 24983.333 | I6: =G6+H6 -> 49933.333 | J6: =I6*Assumptions!$C$18 -> 0 | K6: =I6+J6 -> 49933.333
B7: 3 | C7: Y1 | D7: =IF(B7<=12,Assumptions!$C$12*B7/12,IF(B7<=24,Assumptions!$C$12+(Assumptions!$D$12-Assumptions!$C$12)*(B7-12)/12,Assumptions!$D$12+(Assumptions!$E$12-Assumptions!$D$12)*(B7-24)/12)) -> 75 | E7: =IF(B7<=12,Assumptions!$C$13*B7/12,IF(B7<=24,Assumptions!$C$13+(Assumptions!$D$13-Assumptions!$C$13)*(B7-12)/12,Assumptions!$D$13+(Assumptions!$E$13-Assumptions!$D$13)*(B7-24)/12)) -> 25 | F7: =D7+E7 -> 100 | G7: =D7*Assumptions!$C$6 -> 37425 | H7: =E7*Assumptions!$C$7 -> 37475 | I7: =G7+H7 -> 74900 | J7: =I7*Assumptions!$C$18 -> 0 | K7: =I7+J7 -> 74900
B8: 4 | C8: Y1 | D8: =IF(B8<=12,Assumptions!$C$12*B8/12,IF(B8<=24,Assumptions!$C$12+(Assumptions!$D$12-Assumptions!$C$12)*(B8-12)/12,Assumptions!$D$12+(Assumptions!$E$12-Assumptions!$D$12)*(B8-24)/12)) -> 100 | E8: =IF(B8<=12,Assumptions!$C$13*B8/12,IF(B8<=24,Assumptions!$C$13+(Assumptions!$D$13-Assumptions!$C$13)*(B8-12)/12,Assumptions!$D$13+(Assumptions!$E$13-Assumptions!$D$13)*(B8-24)/12)) -> 33.333333 | F8: =D8+E8 -> 133.33333 | G8: =D8*Assumptions!$C$6 -> 49900 | H8: =E8*Assumptions!$C$7 -> 49966.667 | I8: =G8+H8 -> 99866.667 | J8: =I8*Assumptions!$C$18 -> 0 | K8: =I8+J8 -> 99866.667
B9: 5 | C9: Y1 | D9: =IF(B9<=12,Assumptions!$C$12*B9/12,IF(B9<=24,Assumptions!$C$12+(Assumptions!$D$12-Assumptions!$C$12)*(B9-12)/12,Assumptions!$D$12+(Assumptions!$E$12-Assumptions!$D$12)*(B9-24)/12)) -> 125 | E9: =IF(B9<=12,Assumptions!$C$13*B9/12,IF(B9<=24,Assumptions!$C$13+(Assumptions!$D$13-Assumptions!$C$13)*(B9-12)/12,Assumptions!$D$13+(Assumptions!$E$13-Assumptions!$D$13)*(B9-24)/12)) -> 41.666667 | F9: =D9+E9 -> 166.66667 | G9: =D9*Assumptions!$C$6 -> 62375 | H9: =E9*Assumptions!$C$7 -> 62458.333 | I9: =G9+H9 -> 124833.33 | J9: =I9*Assumptions!$C$18 -> 0 | K9: =I9+J9 -> 124833.33
B10: 6 | C10: Y1 | D10: =IF(B10<=12,Assumptions!$C$12*B10/12,IF(B10<=24,Assumptions!$C$12+(Assumptions!$D$12-Assumptions!$C$12)*(B10-12)/12,Assumptions!$D$12+(Assumptions!$E$12-Assumptions!$D$12)*(B10-24)/12)) -> 150 | E10: =IF(B10<=12,Assumptions!$C$13*B10/12,IF(B10<=24,Assumptions!$C$13+(Assumptions!$D$13-Assumptions!$C$13)*(B10-12)/12,Assumptions!$D$13+(Assumptions!$E$13-Assumptions!$D$13)*(B10-24)/12)) -> 50 | F10: =D10+E10 -> 200 | G10: =D10*Assumptions!$C$6 -> 74850 | H10: =E10*Assumptions!$C$7 -> 74950 | I10: =G10+H10 -> 149800 | J10: =I10*Assumptions!$C$18 -> 0 | K10: =I10+J10 -> 149800
B11: 7 | C11: Y1 | D11: =IF(B11<=12,Assumptions!$C$12*B11/12,IF(B11<=24,Assumptions!$C$12+(Assumptions!$D$12-Assumptions!$C$12)*(B11-12)/12,Assumptions!$D$12+(Assumptions!$E$12-Assumptions!$D$12)*(B11-24)/12)) -> 175 | E11: =IF(B11<=12,Assumptions!$C$13*B11/12,IF(B11<=24,Assumptions!$C$13+(Assumptions!$D$13-Assumptions!$C$13)*(B11-12)/12,Assumptions!$D$13+(Assumptions!$E$13-Assumptions!$D$13)*(B11-24)/12)) -> 58.333333 | F11: =D11+E11 -> 233.33333 | G11: =D11*Assumptions!$C$6 -> 87325 | H11: =E11*Assumptions!$C$7 -> 87441.667 | I11: =G11+H11 -> 174766.67 | J11: =I11*Assumptions!$C$18 -> 0 | K11: =I11+J11 -> 174766.67
B12: 8 | C12: Y1 | D12: =IF(B12<=12,Assumptions!$C$12*B12/12,IF(B12<=24,Assumptions!$C$12+(Assumptions!$D$12-Assumptions!$C$12)*(B12-12)/12,Assumptions!$D$12+(Assumptions!$E$12-Assumptions!$D$12)*(B12-24)/12)) -> 200 | E12: =IF(B12<=12,Assumptions!$C$13*B12/12,IF(B12<=24,Assumptions!$C$13+(Assumptions!$D$13-Assumptions!$C$13)*(B12-12)/12,Assumptions!$D$13+(Assumptions!$E$13-Assumptions!$D$13)*(B12-24)/12)) -> 66.666667 | F12: =D12+E12 -> 266.66667 | G12: =D12*Assumptions!$C$6 -> 99800 | H12: =E12*Assumptions!$C$7 -> 99933.333 | I12: =G12+H12 -> 199733.33 | J12: =I12*Assumptions!$C$18 -> 0 | K12: =I12+J12 -> 199733.33
B13: 9 | C13: Y1 | D13: =IF(B13<=12,Assumptions!$C$12*B13/12,IF(B13<=24,Assumptions!$C$12+(Assumptions!$D$12-Assumptions!$C$12)*(B13-12)/12,Assumptions!$D$12+(Assumptions!$E$12-Assumptions!$D$12)*(B13-24)/12)) -> 225 | E13: =IF(B13<=12,Assumptions!$C$13*B13/12,IF(B13<=24,Assumptions!$C$13+(Assumptions!$D$13-Assumptions!$C$13)*(B13-12)/12,Assumptions!$D$13+(Assumptions!$E$13-Assumptions!$D$13)*(B13-24)/12)) -> 75 | F13: =D13+E13 -> 300 | G13: =D13*Assumptions!$C$6 -> 112275 | H13: =E13*Assumptions!$C$7 -> 112425 | I13: =G13+H13 -> 224700 | J13: =I13*Assumptions!$C$18 -> 0 | K13: =I13+J13 -> 224700
B14: 10 | C14: Y1 | D14: =IF(B14<=12,Assumptions!$C$12*B14/12,IF(B14<=24,Assumptions!$C$12+(Assumptions!$D$12-Assumptions!$C$12)*(B14-12)/12,Assumptions!$D$12+(Assumptions!$E$12-Assumptions!$D$12)*(B14-24)/12)) -> 250 | E14: =IF(B14<=12,Assumptions!$C$13*B14/12,IF(B14<=24,Assumptions!$C$13+(Assumptions!$D$13-Assumptions!$C$13)*(B14-12)/12,Assumptions!$D$13+(Assumptions!$E$13-Assumptions!$D$13)*(B14-24)/12)) -> 83.333333 | F14: =D14+E14 -> 333.33333 | G14: =D14*Assumptions!$C$6 -> 124750 | H14: =E14*Assumptions!$C$7 -> 124916.67 | I14: =G14+H14 -> 249666.67 | J14: =I14*Assumptions!$C$18 -> 0 | K14: =I14+J14 -> 249666.67
B15: 11 | C15: Y1 | D15: =IF(B15<=12,Assumptions!$C$12*B15/12,IF(B15<=24,Assumptions!$C$12+(Assumptions!$D$12-Assumptions!$C$12)*(B15-12)/12,Assumptions!$D$12+(Assumptions!$E$12-Assumptions!$D$12)*(B15-24)/12)) -> 275 | E15: =IF(B15<=12,Assumptions!$C$13*B15/12,IF(B15<=24,Assumptions!$C$13+(Assumptions!$D$13-Assumptions!$C$13)*(B15-12)/12,Assumptions!$D$13+(Assumptions!$E$13-Assumptions!$D$13)*(B15-24)/12)) -> 91.666667 | F15: =D15+E15 -> 366.66667 | G15: =D15*Assumptions!$C$6 -> 137225 | H15: =E15*Assumptions!$C$7 -> 137408.33 | I15: =G15+H15 -> 274633.33 | J15: =I15*Assumptions!$C$18 -> 0 | K15: =I15+J15 -> 274633.33
B16: 12 | C16: Y1 | D16: =IF(B16<=12,Assumptions!$C$12*B16/12,IF(B16<=24,Assumptions!$C$12+(Assumptions!$D$12-Assumptions!$C$12)*(B16-12)/12,Assumptions!$D$12+(Assumptions!$E$12-Assumptions!$D$12)*(B16-24)/12)) -> 300 | E16: =IF(B16<=12,Assumptions!$C$13*B16/12,IF(B16<=24,Assumptions!$C$13+(Assumptions!$D$13-Assumptions!$C$13)*(B16-12)/12,Assumptions!$D$13+(Assumptions!$E$13-Assumptions!$D$13)*(B16-24)/12)) -> 100 | F16: =D16+E16 -> 400 | G16: =D16*Assumptions!$C$6 -> 149700 | H16: =E16*Assumptions!$C$7 -> 149900 | I16: =G16+H16 -> 299600 | J16: =I16*Assumptions!$C$18 -> 0 | K16: =I16+J16 -> 299600
B17: 13 | C17: Y2 | D17: =IF(B17<=12,Assumptions!$C$12*B17/12,IF(B17<=24,Assumptions!$C$12+(Assumptions!$D$12-Assumptions!$C$12)*(B17-12)/12,Assumptions!$D$12+(Assumptions!$E$12-Assumptions!$D$12)*(B17-24)/12)) -> 348.33333 | E17: =IF(B17<=12,Assumptions!$C$13*B17/12,IF(B17<=24,Assumptions!$C$13+(Assumptions!$D$13-Assumptions!$C$13)*(B17-12)/12,Assumptions!$D$13+(Assumptions!$E$13-Assumptions!$D$13)*(B17-24)/12)) -> 151.66667 | F17: =D17+E17 -> 500 | G17: =D17*Assumptions!$C$6 -> 173818.33 | H17: =E17*Assumptions!$C$7 -> 227348.33 | I17: =G17+H17 -> 401166.67 | J17: =I17*Assumptions!$D$18 -> 20058.333 | K17: =I17+J17 -> 421225
B18: 14 | C18: Y2 | D18: =IF(B18<=12,Assumptions!$C$12*B18/12,IF(B18<=24,Assumptions!$C$12+(Assumptions!$D$12-Assumptions!$C$12)*(B18-12)/12,Assumptions!$D$12+(Assumptions!$E$12-Assumptions!$D$12)*(B18-24)/12)) -> 396.66667 | E18: =IF(B18<=12,Assumptions!$C$13*B18/12,IF(B18<=24,Assumptions!$C$13+(Assumptions!$D$13-Assumptions!$C$13)*(B18-12)/12,Assumptions!$D$13+(Assumptions!$E$13-Assumptions!$D$13)*(B18-24)/12)) -> 203.33333 | F18: =D18+E18 -> 600 | G18: =D18*Assumptions!$C$6 -> 197936.67 | H18: =E18*Assumptions!$C$7 -> 304796.67 | I18: =G18+H18 -> 502733.33 | J18: =I18*Assumptions!$D$18 -> 25136.667 | K18: =I18+J18 -> 527870
B19: 15 | C19: Y2 | D19: =IF(B19<=12,Assumptions!$C$12*B19/12,IF(B19<=24,Assumptions!$C$12+(Assumptions!$D$12-Assumptions!$C$12)*(B19-12)/12,Assumptions!$D$12+(Assumptions!$E$12-Assumptions!$D$12)*(B19-24)/12)) -> 445 | E19: =IF(B19<=12,Assumptions!$C$13*B19/12,IF(B19<=24,Assumptions!$C$13+(Assumptions!$D$13-Assumptions!$C$13)*(B19-12)/12,Assumptions!$D$13+(Assumptions!$E$13-Assumptions!$D$13)*(B19-24)/12)) -> 255 | F19: =D19+E19 -> 700 | G19: =D19*Assumptions!$C$6 -> 222055 | H19: =E19*Assumptions!$C$7 -> 382245 | I19: =G19+H19 -> 604300 | J19: =I19*Assumptions!$D$18 -> 30215 | K19: =I19+J19 -> 634515
B20: 16 | C20: Y2 | D20: =IF(B20<=12,Assumptions!$C$12*B20/12,IF(B20<=24,Assumptions!$C$12+(Assumptions!$D$12-Assumptions!$C$12)*(B20-12)/12,Assumptions!$D$12+(Assumptions!$E$12-Assumptions!$D$12)*(B20-24)/12)) -> 493.33333 | E20: =IF(B20<=12,Assumptions!$C$13*B20/12,IF(B20<=24,Assumptions!$C$13+(Assumptions!$D$13-Assumptions!$C$13)*(B20-12)/12,Assumptions!$D$13+(Assumptions!$E$13-Assumptions!$D$13)*(B20-24)/12)) -> 306.66667 | F20: =D20+E20 -> 800 | G20: =D20*Assumptions!$C$6 -> 246173.33 | H20: =E20*Assumptions!$C$7 -> 459693.33 | I20: =G20+H20 -> 705866.67 | J20: =I20*Assumptions!$D$18 -> 35293.333 | K20: =I20+J20 -> 741160
B21: 17 | C21: Y2 | D21: =IF(B21<=12,Assumptions!$C$12*B21/12,IF(B21<=24,Assumptions!$C$12+(Assumptions!$D$12-Assumptions!$C$12)*(B21-12)/12,Assumptions!$D$12+(Assumptions!$E$12-Assumptions!$D$12)*(B21-24)/12)) -> 541.66667 | E21: =IF(B21<=12,Assumptions!$C$13*B21/12,IF(B21<=24,Assumptions!$C$13+(Assumptions!$D$13-Assumptions!$C$13)*(B21-12)/12,Assumptions!$D$13+(Assumptions!$E$13-Assumptions!$D$13)*(B21-24)/12)) -> 358.33333 | F21: =D21+E21 -> 900 | G21: =D21*Assumptions!$C$6 -> 270291.67 | H21: =E21*Assumptions!$C$7 -> 537141.67 | I21: =G21+H21 -> 807433.33 | J21: =I21*Assumptions!$D$18 -> 40371.667 | K21: =I21+J21 -> 847805
B22: 18 | C22: Y2 | D22: =IF(B22<=12,Assumptions!$C$12*B22/12,IF(B22<=24,Assumptions!$C$12+(Assumptions!$D$12-Assumptions!$C$12)*(B22-12)/12,Assumptions!$D$12+(Assumptions!$E$12-Assumptions!$D$12)*(B22-24)/12)) -> 590 | E22: =IF(B22<=12,Assumptions!$C$13*B22/12,IF(B22<=24,Assumptions!$C$13+(Assumptions!$D$13-Assumptions!$C$13)*(B22-12)/12,Assumptions!$D$13+(Assumptions!$E$13-Assumptions!$D$13)*(B22-24)/12)) -> 410 | F22: =D22+E22 -> 1000 | G22: =D22*Assumptions!$C$6 -> 294410 | H22: =E22*Assumptions!$C$7 -> 614590 | I22: =G22+H22 -> 909000 | J22: =I22*Assumptions!$D$18 -> 45450 | K22: =I22+J22 -> 954450
B23: 19 | C23: Y2 | D23: =IF(B23<=12,Assumptions!$C$12*B23/12,IF(B23<=24,Assumptions!$C$12+(Assumptions!$D$12-Assumptions!$C$12)*(B23-12)/12,Assumptions!$D$12+(Assumptions!$E$12-Assumptions!$D$12)*(B23-24)/12)) -> 638.33333 | E23: =IF(B23<=12,Assumptions!$C$13*B23/12,IF(B23<=24,Assumptions!$C$13+(Assumptions!$D$13-Assumptions!$C$13)*(B23-12)/12,Assumptions!$D$13+(Assumptions!$E$13-Assumptions!$D$13)*(B23-24)/12)) -> 461.66667 | F23: =D23+E23 -> 1100 | G23: =D23*Assumptions!$C$6 -> 318528.33 | H23: =E23*Assumptions!$C$7 -> 692038.33 | I23: =G23+H23 -> 1010566.7 | J23: =I23*Assumptions!$D$18 -> 50528.333 | K23: =I23+J23 -> 1061095
B24: 20 | C24: Y2 | D24: =IF(B24<=12,Assumptions!$C$12*B24/12,IF(B24<=24,Assumptions!$C$12+(Assumptions!$D$12-Assumptions!$C$12)*(B24-12)/12,Assumptions!$D$12+(Assumptions!$E$12-Assumptions!$D$12)*(B24-24)/12)) -> 686.66667 | E24: =IF(B24<=12,Assumptions!$C$13*B24/12,IF(B24<=24,Assumptions!$C$13+(Assumptions!$D$13-Assumptions!$C$13)*(B24-12)/12,Assumptions!$D$13+(Assumptions!$E$13-Assumptions!$D$13)*(B24-24)/12)) -> 513.33333 | F24: =D24+E24 -> 1200 | G24: =D24*Assumptions!$C$6 -> 342646.67 | H24: =E24*Assumptions!$C$7 -> 769486.67 | I24: =G24+H24 -> 1112133.3 | J24: =I24*Assumptions!$D$18 -> 55606.667 | K24: =I24+J24 -> 1167740
B25: 21 | C25: Y2 | D25: =IF(B25<=12,Assumptions!$C$12*B25/12,IF(B25<=24,Assumptions!$C$12+(Assumptions!$D$12-Assumptions!$C$12)*(B25-12)/12,Assumptions!$D$12+(Assumptions!$E$12-Assumptions!$D$12)*(B25-24)/12)) -> 735 | E25: =IF(B25<=12,Assumptions!$C$13*B25/12,IF(B25<=24,Assumptions!$C$13+(Assumptions!$D$13-Assumptions!$C$13)*(B25-12)/12,Assumptions!$D$13+(Assumptions!$E$13-Assumptions!$D$13)*(B25-24)/12)) -> 565 | F25: =D25+E25 -> 1300 | G25: =D25*Assumptions!$C$6 -> 366765 | H25: =E25*Assumptions!$C$7 -> 846935 | I25: =G25+H25 -> 1213700 | J25: =I25*Assumptions!$D$18 -> 60685 | K25: =I25+J25 -> 1274385
B26: 22 | C26: Y2 | D26: =IF(B26<=12,Assumptions!$C$12*B26/12,IF(B26<=24,Assumptions!$C$12+(Assumptions!$D$12-Assumptions!$C$12)*(B26-12)/12,Assumptions!$D$12+(Assumptions!$E$12-Assumptions!$D$12)*(B26-24)/12)) -> 783.33333 | E26: =IF(B26<=12,Assumptions!$C$13*B26/12,IF(B26<=24,Assumptions!$C$13+(Assumptions!$D$13-Assumptions!$C$13)*(B26-12)/12,Assumptions!$D$13+(Assumptions!$E$13-Assumptions!$D$13)*(B26-24)/12)) -> 616.66667 | F26: =D26+E26 -> 1400 | G26: =D26*Assumptions!$C$6 -> 390883.33 | H26: =E26*Assumptions!$C$7 -> 924383.33 | I26: =G26+H26 -> 1315266.7 | J26: =I26*Assumptions!$D$18 -> 65763.333 | K26: =I26+J26 -> 1381030
B27: 23 | C27: Y2 | D27: =IF(B27<=12,Assumptions!$C$12*B27/12,IF(B27<=24,Assumptions!$C$12+(Assumptions!$D$12-Assumptions!$C$12)*(B27-12)/12,Assumptions!$D$12+(Assumptions!$E$12-Assumptions!$D$12)*(B27-24)/12)) -> 831.66667 | E27: =IF(B27<=12,Assumptions!$C$13*B27/12,IF(B27<=24,Assumptions!$C$13+(Assumptions!$D$13-Assumptions!$C$13)*(B27-12)/12,Assumptions!$D$13+(Assumptions!$E$13-Assumptions!$D$13)*(B27-24)/12)) -> 668.33333 | F27: =D27+E27 -> 1500 | G27: =D27*Assumptions!$C$6 -> 415001.67 | H27: =E27*Assumptions!$C$7 -> 1001831.7 | I27: =G27+H27 -> 1416833.3 | J27: =I27*Assumptions!$D$18 -> 70841.667 | K27: =I27+J27 -> 1487675
B28: 24 | C28: Y2 | D28: =IF(B28<=12,Assumptions!$C$12*B28/12,IF(B28<=24,Assumptions!$C$12+(Assumptions!$D$12-Assumptions!$C$12)*(B28-12)/12,Assumptions!$D$12+(Assumptions!$E$12-Assumptions!$D$12)*(B28-24)/12)) -> 880 | E28: =IF(B28<=12,Assumptions!$C$13*B28/12,IF(B28<=24,Assumptions!$C$13+(Assumptions!$D$13-Assumptions!$C$13)*(B28-12)/12,Assumptions!$D$13+(Assumptions!$E$13-Assumptions!$D$13)*(B28-24)/12)) -> 720 | F28: =D28+E28 -> 1600 | G28: =D28*Assumptions!$C$6 -> 439120 | H28: =E28*Assumptions!$C$7 -> 1079280 | I28: =G28+H28 -> 1518400 | J28: =I28*Assumptions!$D$18 -> 75920 | K28: =I28+J28 -> 1594320
B29: 25 | C29: Y3 | D29: =IF(B29<=12,Assumptions!$C$12*B29/12,IF(B29<=24,Assumptions!$C$12+(Assumptions!$D$12-Assumptions!$C$12)*(B29-12)/12,Assumptions!$D$12+(Assumptions!$E$12-Assumptions!$D$12)*(B29-24)/12)) -> 946.66667 | E29: =IF(B29<=12,Assumptions!$C$13*B29/12,IF(B29<=24,Assumptions!$C$13+(Assumptions!$D$13-Assumptions!$C$13)*(B29-12)/12,Assumptions!$D$13+(Assumptions!$E$13-Assumptions!$D$13)*(B29-24)/12)) -> 870 | F29: =D29+E29 -> 1816.6667 | G29: =D29*Assumptions!$C$6 -> 472386.67 | H29: =E29*Assumptions!$C$7 -> 1304130 | I29: =G29+H29 -> 1776516.7 | J29: =I29*Assumptions!$E$18 -> 177651.67 | K29: =I29+J29 -> 1954168.3
B30: 26 | C30: Y3 | D30: =IF(B30<=12,Assumptions!$C$12*B30/12,IF(B30<=24,Assumptions!$C$12+(Assumptions!$D$12-Assumptions!$C$12)*(B30-12)/12,Assumptions!$D$12+(Assumptions!$E$12-Assumptions!$D$12)*(B30-24)/12)) -> 1013.3333 | E30: =IF(B30<=12,Assumptions!$C$13*B30/12,IF(B30<=24,Assumptions!$C$13+(Assumptions!$D$13-Assumptions!$C$13)*(B30-12)/12,Assumptions!$D$13+(Assumptions!$E$13-Assumptions!$D$13)*(B30-24)/12)) -> 1020 | F30: =D30+E30 -> 2033.3333 | G30: =D30*Assumptions!$C$6 -> 505653.33 | H30: =E30*Assumptions!$C$7 -> 1528980 | I30: =G30+H30 -> 2034633.3 | J30: =I30*Assumptions!$E$18 -> 203463.33 | K30: =I30+J30 -> 2238096.7
B31: 27 | C31: Y3 | D31: =IF(B31<=12,Assumptions!$C$12*B31/12,IF(B31<=24,Assumptions!$C$12+(Assumptions!$D$12-Assumptions!$C$12)*(B31-12)/12,Assumptions!$D$12+(Assumptions!$E$12-Assumptions!$D$12)*(B31-24)/12)) -> 1080 | E31: =IF(B31<=12,Assumptions!$C$13*B31/12,IF(B31<=24,Assumptions!$C$13+(Assumptions!$D$13-Assumptions!$C$13)*(B31-12)/12,Assumptions!$D$13+(Assumptions!$E$13-Assumptions!$D$13)*(B31-24)/12)) -> 1170 | F31: =D31+E31 -> 2250 | G31: =D31*Assumptions!$C$6 -> 538920 | H31: =E31*Assumptions!$C$7 -> 1753830 | I31: =G31+H31 -> 2292750 | J31: =I31*Assumptions!$E$18 -> 229275 | K31: =I31+J31 -> 2522025
B32: 28 | C32: Y3 | D32: =IF(B32<=12,Assumptions!$C$12*B32/12,IF(B32<=24,Assumptions!$C$12+(Assumptions!$D$12-Assumptions!$C$12)*(B32-12)/12,Assumptions!$D$12+(Assumptions!$E$12-Assumptions!$D$12)*(B32-24)/12)) -> 1146.6667 | E32: =IF(B32<=12,Assumptions!$C$13*B32/12,IF(B32<=24,Assumptions!$C$13+(Assumptions!$D$13-Assumptions!$C$13)*(B32-12)/12,Assumptions!$D$13+(Assumptions!$E$13-Assumptions!$D$13)*(B32-24)/12)) -> 1320 | F32: =D32+E32 -> 2466.6667 | G32: =D32*Assumptions!$C$6 -> 572186.67 | H32: =E32*Assumptions!$C$7 -> 1978680 | I32: =G32+H32 -> 2550866.7 | J32: =I32*Assumptions!$E$18 -> 255086.67 | K32: =I32+J32 -> 2805953.3
B33: 29 | C33: Y3 | D33: =IF(B33<=12,Assumptions!$C$12*B33/12,IF(B33<=24,Assumptions!$C$12+(Assumptions!$D$12-Assumptions!$C$12)*(B33-12)/12,Assumptions!$D$12+(Assumptions!$E$12-Assumptions!$D$12)*(B33-24)/12)) -> 1213.3333 | E33: =IF(B33<=12,Assumptions!$C$13*B33/12,IF(B33<=24,Assumptions!$C$13+(Assumptions!$D$13-Assumptions!$C$13)*(B33-12)/12,Assumptions!$D$13+(Assumptions!$E$13-Assumptions!$D$13)*(B33-24)/12)) -> 1470 | F33: =D33+E33 -> 2683.3333 | G33: =D33*Assumptions!$C$6 -> 605453.33 | H33: =E33*Assumptions!$C$7 -> 2203530 | I33: =G33+H33 -> 2808983.3 | J33: =I33*Assumptions!$E$18 -> 280898.33 | K33: =I33+J33 -> 3089881.7
B34: 30 | C34: Y3 | D34: =IF(B34<=12,Assumptions!$C$12*B34/12,IF(B34<=24,Assumptions!$C$12+(Assumptions!$D$12-Assumptions!$C$12)*(B34-12)/12,Assumptions!$D$12+(Assumptions!$E$12-Assumptions!$D$12)*(B34-24)/12)) -> 1280 | E34: =IF(B34<=12,Assumptions!$C$13*B34/12,IF(B34<=24,Assumptions!$C$13+(Assumptions!$D$13-Assumptions!$C$13)*(B34-12)/12,Assumptions!$D$13+(Assumptions!$E$13-Assumptions!$D$13)*(B34-24)/12)) -> 1620 | F34: =D34+E34 -> 2900 | G34: =D34*Assumptions!$C$6 -> 638720 | H34: =E34*Assumptions!$C$7 -> 2428380 | I34: =G34+H34 -> 3067100 | J34: =I34*Assumptions!$E$18 -> 306710 | K34: =I34+J34 -> 3373810
B35: 31 | C35: Y3 | D35: =IF(B35<=12,Assumptions!$C$12*B35/12,IF(B35<=24,Assumptions!$C$12+(Assumptions!$D$12-Assumptions!$C$12)*(B35-12)/12,Assumptions!$D$12+(Assumptions!$E$12-Assumptions!$D$12)*(B35-24)/12)) -> 1346.6667 | E35: =IF(B35<=12,Assumptions!$C$13*B35/12,IF(B35<=24,Assumptions!$C$13+(Assumptions!$D$13-Assumptions!$C$13)*(B35-12)/12,Assumptions!$D$13+(Assumptions!$E$13-Assumptions!$D$13)*(B35-24)/12)) -> 1770 | F35: =D35+E35 -> 3116.6667 | G35: =D35*Assumptions!$C$6 -> 671986.67 | H35: =E35*Assumptions!$C$7 -> 2653230 | I35: =G35+H35 -> 3325216.7 | J35: =I35*Assumptions!$E$18 -> 332521.67 | K35: =I35+J35 -> 3657738.3
B36: 32 | C36: Y3 | D36: =IF(B36<=12,Assumptions!$C$12*B36/12,IF(B36<=24,Assumptions!$C$12+(Assumptions!$D$12-Assumptions!$C$12)*(B36-12)/12,Assumptions!$D$12+(Assumptions!$E$12-Assumptions!$D$12)*(B36-24)/12)) -> 1413.3333 | E36: =IF(B36<=12,Assumptions!$C$13*B36/12,IF(B36<=24,Assumptions!$C$13+(Assumptions!$D$13-Assumptions!$C$13)*(B36-12)/12,Assumptions!$D$13+(Assumptions!$E$13-Assumptions!$D$13)*(B36-24)/12)) -> 1920 | F36: =D36+E36 -> 3333.3333 | G36: =D36*Assumptions!$C$6 -> 705253.33 | H36: =E36*Assumptions!$C$7 -> 2878080 | I36: =G36+H36 -> 3583333.3 | J36: =I36*Assumptions!$E$18 -> 358333.33 | K36: =I36+J36 -> 3941666.7
B37: 33 | C37: Y3 | D37: =IF(B37<=12,Assumptions!$C$12*B37/12,IF(B37<=24,Assumptions!$C$12+(Assumptions!$D$12-Assumptions!$C$12)*(B37-12)/12,Assumptions!$D$12+(Assumptions!$E$12-Assumptions!$D$12)*(B37-24)/12)) -> 1480 | E37: =IF(B37<=12,Assumptions!$C$13*B37/12,IF(B37<=24,Assumptions!$C$13+(Assumptions!$D$13-Assumptions!$C$13)*(B37-12)/12,Assumptions!$D$13+(Assumptions!$E$13-Assumptions!$D$13)*(B37-24)/12)) -> 2070 | F37: =D37+E37 -> 3550 | G37: =D37*Assumptions!$C$6 -> 738520 | H37: =E37*Assumptions!$C$7 -> 3102930 | I37: =G37+H37 -> 3841450 | J37: =I37*Assumptions!$E$18 -> 384145 | K37: =I37+J37 -> 4225595
B38: 34 | C38: Y3 | D38: =IF(B38<=12,Assumptions!$C$12*B38/12,IF(B38<=24,Assumptions!$C$12+(Assumptions!$D$12-Assumptions!$C$12)*(B38-12)/12,Assumptions!$D$12+(Assumptions!$E$12-Assumptions!$D$12)*(B38-24)/12)) -> 1546.6667 | E38: =IF(B38<=12,Assumptions!$C$13*B38/12,IF(B38<=24,Assumptions!$C$13+(Assumptions!$D$13-Assumptions!$C$13)*(B38-12)/12,Assumptions!$D$13+(Assumptions!$E$13-Assumptions!$D$13)*(B38-24)/12)) -> 2220 | F38: =D38+E38 -> 3766.6667 | G38: =D38*Assumptions!$C$6 -> 771786.67 | H38: =E38*Assumptions!$C$7 -> 3327780 | I38: =G38+H38 -> 4099566.7 | J38: =I38*Assumptions!$E$18 -> 409956.67 | K38: =I38+J38 -> 4509523.3
B39: 35 | C39: Y3 | D39: =IF(B39<=12,Assumptions!$C$12*B39/12,IF(B39<=24,Assumptions!$C$12+(Assumptions!$D$12-Assumptions!$C$12)*(B39-12)/12,Assumptions!$D$12+(Assumptions!$E$12-Assumptions!$D$12)*(B39-24)/12)) -> 1613.3333 | E39: =IF(B39<=12,Assumptions!$C$13*B39/12,IF(B39<=24,Assumptions!$C$13+(Assumptions!$D$13-Assumptions!$C$13)*(B39-12)/12,Assumptions!$D$13+(Assumptions!$E$13-Assumptions!$D$13)*(B39-24)/12)) -> 2370 | F39: =D39+E39 -> 3983.3333 | G39: =D39*Assumptions!$C$6 -> 805053.33 | H39: =E39*Assumptions!$C$7 -> 3552630 | I39: =G39+H39 -> 4357683.3 | J39: =I39*Assumptions!$E$18 -> 435768.33 | K39: =I39+J39 -> 4793451.7
B40: 36 | C40: Y3 | D40: =IF(B40<=12,Assumptions!$C$12*B40/12,IF(B40<=24,Assumptions!$C$12+(Assumptions!$D$12-Assumptions!$C$12)*(B40-12)/12,Assumptions!$D$12+(Assumptions!$E$12-Assumptions!$D$12)*(B40-24)/12)) -> 1680 | E40: =IF(B40<=12,Assumptions!$C$13*B40/12,IF(B40<=24,Assumptions!$C$13+(Assumptions!$D$13-Assumptions!$C$13)*(B40-12)/12,Assumptions!$D$13+(Assumptions!$E$13-Assumptions!$D$13)*(B40-24)/12)) -> 2520 | F40: =D40+E40 -> 4200 | G40: =D40*Assumptions!$C$6 -> 838320 | H40: =E40*Assumptions!$C$7 -> 3777480 | I40: =G40+H40 -> 4615800 | J40: =I40*Assumptions!$E$18 -> 461580 | K40: =I40+J40 -> 5077380
B42: ANNUAL SUMMARY
...

Sheet Profit & Loss Statement
B1: PROFIT & LOSS STATEMENT (ILLUSTRATIVE)
B2: All figures annual, in Indian Rupees (₹). Linked to Revenue Projection and Assumptions sheets.
B4: Line Item | C4: Year 1 | D4: Year 2 | E4: Year 3 | F4: Notes
B5: Total Revenue | C5: ='Revenue Projection'!C46 -> 1947400 | D5: ='Revenue Projection'!D46 -> 12093270 | E5: ='Revenue Projection'!E46 -> 42189290
B6: Cost of Goods Sold (Cloud infra & hosting) | C6: =Assumptions!C23 -> 600000 | D6: =Assumptions!D23 -> 1500000 | E6: =Assumptions!E23 -> 2800000
B7: Gross Profit | C7: =C5-C6 -> 1347400 | D7: =D5-D6 -> 10593270 | E7: =E5-E6 -> 39389290
B8: Gross Margin % | C8: =C7/C5 -> 0.69189689 | D8: =D7/D5 -> 0.87596407 | E8: =E7/E5 -> 0.93363245
B10: Operating Expenses:
B11: Team costs (salaries) | C11: =Assumptions!C22 -> 6400000 | D11: =Assumptions!D22 -> 12600000 | E11: =Assumptions!E22 -> 20000000
B12: Marketing & channel enablement | C12: =Assumptions!C24 -> 800000 | D12: =Assumptions!D24 -> 2000000 | E12: =Assumptions!E24 -> 3000000
B13: General & administrative | C13: =Assumptions!C25 -> 500000 | D13: =Assumptions!D25 -> 1000000 | E13: =Assumptions!E25 -> 1500000
B14: Total Operating Expenses | C14: =SUM(C11:C13) -> 7700000 | D14: =SUM(D11:D13) -> 15600000 | E14: =SUM(E11:E13) -> 24500000
B16: EBITDA | C16: =C7-C14 -> -6352600 | D16: =D7-D14 -> -5006730 | E16: =E7-E14 -> 14889290
B17: EBITDA Margin % | C17: =C16/C5 -> -3.262093 | D17: =D16/D5 -> -0.41400961 | E17: =E16/E5 -> 0.35291634
B18: Depreciation & Amortization | C18: =('Startup Cost Estimation'!$C$5+'Startup Cost Estimation'!$C$6+'Startup Cost Estimation'!$C$7)/Assumptions!$C$42 -> 640000 | D18: =('Startup Cost Estimation'!$C$5+'Startup Cost Estimation'!$C$6+'Startup Cost Estimation'!$C$7)/Assumptions!$C$42 -> 640000 | E18: =('Startup Cost Estimation'!$C$5+'Startup Cost Estimation'!$C$6+'Startup Cost Estimation'!$C$7)/Assumptions!$C$42 -> 640000 | F18: Straight-line over depreciation period on Product Dev + Cloud Setup + Branding capex
B19: EBIT (Operating Profit) | C19: =C16-C18 -> -6992600 | D19: =D16-D18 -> -5646730 | E19: =E16-E18 -> 14249290
B20: Tax | C20: =MAX(C19,0)*Assumptions!$C$39 -> 0 | D20: =MAX(D19,0)*Assumptions!$C$39 -> 0 | E20: =MAX(E19,0)*Assumptions!$C$39 -> 3562322.5
B21: Net Profit / (Loss) | C21: =C19-C20 -> -6992600 | D21: =D19-D20 -> -5646730 | E21: =E19-E20 -> 10686968
B22: Net Profit Margin % | C22: =C21/C5 -> -3.5907364 | D22: =D21/D5 -> -0.46693161 | E22: =E21/E5 -> 0.25330996
B24: Year | C24: Revenue | D24: EBITDA | E24: Net Profit
B25: Year 1 | C25: =C5 -> 1947400 | D25: =C16 -> -6352600 | E25: =C21 -> -6992600
B26: Year 2 | C26: =D5 -> 12093270 | D26: =D16 -> -5006730 | E26: =D21 -> -5646730
B27: Year 3 | C27: =E5 -> 42189290 | D27: =E16 -> 14889290 | E27: =E21 -> 10686968

Sheet Cash Flow Statement
B1: CASH FLOW STATEMENT (ILLUSTRATIVE)
B2: Simplified indirect-method cash flow. Assumes founding/seed capital equal to total startup cost is raised in Year 1.
B4: Line Item | C4: Year 1 | D4: Year 2 | E4: Year 3 | F4: Notes
B5: Operating Activities
B6: Net Profit / (Loss) | C6: ='Profit & Loss Statement'!C21 -> -6992600 | D6: ='Profit & Loss Statement'!D21 -> -5646730 | E6: ='Profit & Loss Statement'!E21 -> 10686968
B7: Add back: Depreciation & Amortization | C7: ='Profit & Loss Statement'!C18 -> 640000 | D7: ='Profit & Loss Statement'!D18 -> 640000 | E7: ='Profit & Loss Statement'!E18 -> 640000
B8: Net Cash from Operating Activities | C8: =C6+C7 -> -6352600 | D8: =D6+D7 -> -5006730 | E8: =E6+E7 -> 11326968
B10: Investing Activities
B11: Capital expenditure (startup build-out) | C11: =-'Startup Cost Estimation'!C14 -> -5940000 | D11: 0 | E11: 0
B12: Net Cash from Investing Activities | C12: =C11 -> -5940000 | D12: =D11 -> 0 | E12: =E11 -> 0
B14: Financing Activities
B15: Founding / seed capital raised | C15: ='Startup Cost Estimation'!C14 -> 5940000 | D15: 0 | E15: 0
B16: Net Cash from Financing Activities | C16: =C15 -> 5940000 | D16: =D15 -> 0 | E16: =E15 -> 0
B18: Net Change in Cash | C18: =C8+C12+C16 -> -6352600 | D18: =D8+D12+D16 -> -5006730 | E18: =E8+E12+E16 -> 11326968
B19: Opening Cash Balance | C19: 0 | D19: =C20 -> -6352600 | E19: =D20 -> -11359330
B20: Closing Cash Balance | C20: =C19+C18 -> -6352600 | D20: =D19+D18 -> -11359330 | E20: =E19+E18 -> -32362.5
B22: Note: A simplified model with no working-capital or debt-financing assumptions. Illustrative only.

Sheet Break-even Analysis
B1: BREAK-EVEN ANALYSIS
B2: Contribution-margin basis break-even, per Business Plan Ch.36. Assumes early-period ARPU and variable cost per subscriber.
B4: Variable | C4: Value
B5: Blended ARPU (₹/month) | C5: =Assumptions!C30 -> 750
B6: Variable cost per subscriber (₹/month) | C6: =Assumptions!C31 -> 100
B7: Contribution margin per subscriber (₹/month) | C7: =Assumptions!C32 -> 650
B8: Estimated fixed monthly operating cost (Year 1 basis) | C8: =Assumptions!C26/12 -> 691666.67
B10: Break-even Subscribers | C10: =ROUNDUP(C8/C7,0) -> 1065
B11: Break-even Monthly Revenue (₹) | C11: =C10*C5 -> 798750
B12: Estimated Break-even Month (subscriber count crosses threshold) | C12: =IFERROR(MATCH(TRUE(),INDEX('Revenue Projection'!F5:F40>=C10,0),0),"Beyond Year 3") -> 19 | D12: Array-style MATCH against monthly subscriber build on Revenue Projection sheet
B14: Dividing the estimated fixed monthly cost base by the contribution margin per subscriber gives an illustrative break-even point of approximately 1,050-1,100 subscribing organisations, expected to be crossed roughly two-thirds of the way through Year 2 (Business Plan Ch.36).
B20: Month | C20: Total Subscribers | D20: Monthly Revenue (₹) | E20: Fixed Monthly Cost (₹)
B21: 1 | C21: ='Revenue Projection'!F5 -> 33.333333 | D21: ='Revenue Projection'!K5 -> 24966.667 | E21: =$C$8 -> 691666.67
B22: 4 | C22: ='Revenue Projection'!F8 -> 133.33333 | D22: ='Revenue Projection'!K8 -> 99866.667 | E22: =$C$8 -> 691666.67
B23: 7 | C23: ='Revenue Projection'!F11 -> 233.33333 | D23: ='Revenue Projection'!K11 -> 174766.67 | E23: =$C$8 -> 691666.67
B24: 10 | C24: ='Revenue Projection'!F14 -> 333.33333 | D24: ='Revenue Projection'!K14 -> 249666.67 | E24: =$C$8 -> 691666.67
B25: 13 | C25: ='Revenue Projection'!F17 -> 500 | D25: ='Revenue Projection'!K17 -> 421225 | E25: =$C$8 -> 691666.67
B26: 16 | C26: ='Revenue Projection'!F20 -> 800 | D26: ='Revenue Projection'!K20 -> 741160 | E26: =$C$8 -> 691666.67
B27: 19 | C27: ='Revenue Projection'!F23 -> 1100 | D27: ='Revenue Projection'!K23 -> 1061095 | E27: =$C$8 -> 691666.67
B28: 22 | C28: ='Revenue Projection'!F26 -> 1400 | D28: ='Revenue Projection'!K26 -> 1381030 | E28: =$C$8 -> 691666.67
B29: 25 | C29: ='Revenue Projection'!F29 -> 1816.6667 | D29: ='Revenue Projection'!K29 -> 1954168.3 | E29: =$C$8 -> 691666.67
B30: 28 | C30: ='Revenue Projection'!F32 -> 2466.6667 | D30: ='Revenue Projection'!K32 -> 2805953.3 | E30: =$C$8 -> 691666.67
B31: 31 | C31: ='Revenue Projection'!F35 -> 3116.6667 | D31: ='Revenue Projection'!K35 -> 3657738.3 | E31: =$C$8 -> 691666.67
B32: 34 | C32: ='Revenue Projection'!F38 -> 3766.6667 | D32: ='Revenue Projection'!K38 -> 4509523.3 | E32: =$C$8 -> 691666.67

Sheet KPI Dashboard
B1: CYBERSHIELD360 — KPI DASHBOARD
B2: Live-linked key performance indicators, updating automatically from Revenue Projection, P&L, and Assumptions.
B4: KPI | C4: Year 1 | D4: Year 2 | E4: Year 3
B5: MRR at year-end (₹/month) | C5: ='Revenue Projection'!K16 -> 299600 | D5: ='Revenue Projection'!K28 -> 1594320 | E5: ='Revenue Projection'!K40 -> 5077380
B6: Total ARR — Subscription + Add-on run-rate (₹) | C6: =C5*12 -> 3595200 | D6: =D5*12 -> 19131840 | E6: =E5*12 -> 60928560
B7: Customer Count (year-end) | C7: ='Revenue Projection'!C48 -> 400 | D7: ='Revenue Projection'!D48 -> 1600 | E7: ='Revenue Projection'!E48 -> 4200
B8: ARPU — Avg. Revenue Per User (₹/month) | C8: =C5/C7 -> 749 | D8: =D5/D7 -> 996.45 | E8: =E5/E7 -> 1208.9
B9: Gross Margin % | C9: ='Profit & Loss Statement'!C8 -> 0.69189689 | D9: ='Profit & Loss Statement'!D8 -> 0.87596407 | E9: ='Profit & Loss Statement'!E8 -> 0.93363245
B10: Net Margin % | C10: ='Profit & Loss Statement'!C22 -> -3.5907364 | D10: ='Profit & Loss Statement'!D22 -> -0.46693161 | E10: ='Profit & Loss Statement'!E22 -> 0.25330996
B11: CAC — Customer Acquisition Cost (₹, illustrative) | C11: =Assumptions!C24/'Revenue Projection'!C48 -> 2000 | D11: =Assumptions!D24/('Revenue Projection'!D48-'Revenue Projection'!C48) -> 1666.6667 | E11: =Assumptions!E24/('Revenue Projection'!E48-'Revenue Projection'!D48) -> 1153.8462
B12: LTV — Customer Lifetime Value (₹) | C12: =Assumptions!$C$35 -> 21250 | D12: =Assumptions!$C$35 -> 21250 | E12: =Assumptions!$C$35 -> 21250
B13: LTV : CAC Ratio | C13: =C12/C11 -> 10.625 | D13: =D12/D11 -> 12.75 | E13: =E12/E11 -> 18.416667
B14: Annual ARR Growth % | C14: ="n/a" -> n/a | D14: =D6/C6-1 -> 4.3214953 | E14: =E6/D6-1 -> 2.1846681
B15: Avg. Monthly Revenue Growth % (in-year) | C15: =(C5/('Revenue Projection'!K5))^(1/11)-1 -> 0.25345107 | D15: =(D5/('Revenue Projection'!K17))^(1/11)-1 -> 0.12862855 | E15: =(E5/('Revenue Projection'!K29))^(1/11)-1 -> 0.090681564
B17: REVENUE MIX — YEAR 3 (₹)
B18: Revenue Stream | C18: Amount (₹)
B19: Starter Shield subscriptions | C19: =SUMIFS('Revenue Projection'!G:G,'Revenue Projection'!C:C,"Y3") -> 7864240
B20: Business Shield subscriptions | C20: =SUMIFS('Revenue Projection'!H:H,'Revenue Projection'!C:C,"Y3") -> 30489660
B21: Consulting & training add-ons | C21: =SUMIFS('Revenue Projection'!J:J,'Revenue Projection'!C:C,"Y3") -> 3835390
B24: SUBSCRIBER GROWTH BY YEAR
B25: Year | C25: Starter | D25: Business | E25: Total
B26: Year 1 | C26: =Assumptions!C12 -> 300 | D26: =Assumptions!C13 -> 100 | E26: =C26+D26 -> 400
B27: Year 2 | C27: =Assumptions!D12 -> 880 | D27: =Assumptions!D13 -> 720 | E27: =C27+D27 -> 1600
B28: Year 3 | C28: =Assumptions!E12 -> 1680 | D28: =Assumptions!E13 -> 2520 | E28: =C28+D28 -> 4200
B32: Gauge Helper — LTV:CAC (Year 3, capped at 5x for display)
B33: Achieved | C33: =MIN(E13,5) -> 5
B34: Remaining (of 5x scale) | C34: =5-C33 -> 0

Sheet Scenario Analysis
B1: SCENARIO ANALYSIS
B2: Best / Expected / Worst cases apply the scenario multipliers (Assumptions §G) to Year-3 subscriber counts, holding pricing and cost ratios constant. Illustrative only.
B4: Metric | C4: Best Case | D4: Expected Case | E4: Worst Case
B5: Year 3 Total Subscribers | C5: ='Revenue Projection'!E48*Assumptions!C47 -> 5040 | D5: ='Revenue Projection'!E48*Assumptions!C48 -> 4200 | E5: ='Revenue Projection'!E48*Assumptions!C49 -> 3150
B6: Blended ARPU (₹/month, actual) | C6: ='KPI Dashboard'!E8 -> 1208.9 | D6: ='KPI Dashboard'!E8 -> 1208.9 | E6: ='KPI Dashboard'!E8 -> 1208.9
B7: Year 3 Annualised Revenue (₹) | C7: =C5*C6*12 -> 73114272 | D7: =D5*D6*12 -> 60928560 | E7: =E5*E6*12 -> 45696420
B8: Gross Margin % (assumption) | C8: ='Profit & Loss Statement'!E8 -> 0.93363245 | D8: ='Profit & Loss Statement'!E8 -> 0.93363245 | E8: ='Profit & Loss Statement'!E8 -> 0.93363245
B9: Year 3 Operating Expenses (₹, held constant) | C9: =Assumptions!E26 -> 27300000 | D9: =Assumptions!E26 -> 27300000 | E9: =Assumptions!E26 -> 27300000
B10: Illustrative Year 3 Operating Profit (₹) | C10: =C7*C8-C9 -> 40961857 | D10: =D7*D8-D9 -> 29584880 | E10: =E7*E8-E9 -> 15363660
B11: Implied Operating Margin % | C11: =C10/C7 -> 0.56024433 | D11: =D10/D7 -> 0.48556671 | E11: =E10/E7 -> 0.33621147
B14: Best/Worst cases flex subscriber acquisition only; pricing, ARPU, gross margin and the cost base are held constant for simplicity. In practice a materially higher- or lower-growth scenario would likely also shift the cost base and sales/marketing spend; this simplification is a portfolio-level illustration, not a full operating plan re-forecast.
B19: Scenario | C19: Revenue | D19: Operating Profit
B20: Best Case | C20: =C7 -> 73114272 | D20: =C10 -> 40961857
B21: Expected Case | C21: =D7 -> 60928560 | D21: =D10 -> 29584880
B22: Worst Case | C22: =E7 -> 45696420 | D22: =E10 -> 15363660

Sheet Investment Summary
B1: INVESTMENT SUMMARY
B2: Illustrative funding and return summary for MBA/MBM portfolio and investor-documentation purposes. No specific funding ask or valuation is stated in source materials; figures here are derived transparently from the Startup Cost and P&L sheets.
B4: FUNDING REQUIRED
B5: Total Startup Capital Required (₹) | C5: ='Startup Cost Estimation'!C14 -> 5940000 | E5: Equals Total Estimated Startup Cost incl. contingency (Startup Cost Estimation sheet)
B7: USE OF FUNDS
B8: Category | C8: Amount (₹) | D8: % of Total
B9: ='Startup Cost Estimation'!B5 -> Product development (platform, mobile app, initial AI models) | C9: ='Startup Cost Estimation'!C5 -> 2500000 | D9: =C9/$C$5 -> 0.42087542
B10: ='Startup Cost Estimation'!B6 -> Cloud infrastructure setup | C10: ='Startup Cost Estimation'!C6 -> 400000 | D10: =C10/$C$5 -> 0.067340067
B11: ='Startup Cost Estimation'!B7 -> Branding, website & marketing collateral | C11: ='Startup Cost Estimation'!C7 -> 300000 | D11: =C11/$C$5 -> 0.050505051
B12: ='Startup Cost Estimation'!B8 -> Legal, compliance & incorporation | C12: ='Startup Cost Estimation'!C8 -> 200000 | D12: =C12/$C$5 -> 0.033670034
B13: ='Startup Cost Estimation'!B9 -> Founding team runway (approx. 6 months) | C13: ='Startup Cost Estimation'!C9 -> 1500000 | D13: =C13/$C$5 -> 0.25252525
B14: ='Startup Cost Estimation'!B10 -> Initial marketing launch budget | C14: ='Startup Cost Estimation'!C10 -> 500000 | D14: =C14/$C$5 -> 0.084175084
B17: ROI PROJECTION (ILLUSTRATIVE)
B18: Year 3 EBITDA (₹) | C18: ='Profit & Loss Statement'!E16 -> 14889290
B19: Year 3 EBITDA as multiple of funding | C19: =C18/C5 -> 2.5066145
B20: Simple 3-Yr Net Profit NPV, discounted (₹) | C20: ='Profit & Loss Statement'!C21/(1+Assumptions!$C$40)^1+'Profit & Loss Statement'!D21/(1+Assumptions!$C$40)^2+'Profit & Loss Statement'!E21/(1+Assumptions!$C$40)^3 -> -3476907.4 | E20: Discounted at illustrative 18% VC hurdle rate (Assumptions §F)
B21: Indicative Year 4 Revenue (₹, at assumed growth) | C21: ='Revenue Projection'!E46*(1+Assumptions!$C$43) -> 59065006 | E21: Illustrative extrapolation only — not a forecast commitment
B23: KEY METRICS SNAPSHOT
B24: Metric | C24: Year 1 | D24: Year 3
B25: Subscribers (year-end) | C25: ='KPI Dashboard'!C7 -> 400 | D25: ='KPI Dashboard'!E7 -> 4200
B26: ARR — run-rate (₹) | C26: ='KPI Dashboard'!C6 -> 3595200 | D26: ='KPI Dashboard'!E6 -> 60928560
B27: Gross Margin % | C27: ='KPI Dashboard'!C9 -> 0.69189689 | D27: ='KPI Dashboard'!E9 -> 0.93363245
B28: LTV : CAC Ratio | C28: ='KPI Dashboard'!C13 -> 10.625 | D28: ='KPI Dashboard'!E13 -> 18.416667
B30: Revenue growth index (Yr1=1.0x -> Yr3) | C30: ='Revenue Projection'!E49 -> 21.664419 | E30: Per Business Plan Ch.35: ~1x -> 5.1x -> 15.4x illustrative growth curve
B33: INVESTOR EXIT POSSIBILITIES (ILLUSTRATIVE)
B34: • Strategic acquisition by a larger cybersecurity, MSSP, or enterprise-SaaS platform seeking SME market entry.
B35: • Private equity buyout once the company reaches consistent operating profitability and scale (post Year 3).
B36: • Secondary sale of founder/early-investor equity in a later growth-stage financing round.
B37: • Continued independent growth toward the vision of becoming India's most trusted SME cybersecurity platform, with optional international expansion (Business Plan Ch.5, Ch.38).
B39: No specific funding round, valuation, or investor terms are stated in CyberShield360's source documents; the above are illustrative, category-level exit pathways typical of an early-stage SaaS business, not commitments or forecasts.
